2020-02-24 00:30:58,694 ERROR: Exception on /reset_password_request [POST]: [in /Users/jinmc/Developer/python/flaskBlog/venv/lib/python3.6/site-packages/flask/app.py:1891]
Traceback (most recent call last):
  File "/Users/jinmc/Developer/python/flaskBlog/venv/lib/python3.6/site-packages/flask/app.py", line 2446, in wsgi_app
    response = self.full_dispatch_request()
  File "/Users/jinmc/Developer/python/flaskBlog/venv/lib/python3.6/site-packages/flask/app.py", line 1951, in full_dispatch_request
    rv = self.handle_user_exception(e)
  File "/Users/jinmc/Developer/python/flaskBlog/venv/lib/python3.6/site-packages/flask/app.py", line 1820, in handle_user_exception
    reraise(exc_type, exc_value, tb)
  File "/Users/jinmc/Developer/python/flaskBlog/venv/lib/python3.6/site-packages/flask/_compat.py", line 39, in reraise
    raise value
  File "/Users/jinmc/Developer/python/flaskBlog/venv/lib/python3.6/site-packages/flask/app.py", line 1949, in full_dispatch_request
    rv = self.dispatch_request()
  File "/Users/jinmc/Developer/python/flaskBlog/venv/lib/python3.6/site-packages/flask/app.py", line 1935, in dispatch_request
    return self.view_functions[rule.endpoint](**req.view_args)
  File "/Users/jinmc/Developer/python/flaskBlog/app/routes.py", line 166, in reset_password_request
    send_password_reset_email(user)
  File "/Users/jinmc/Developer/python/flaskBlog/app/email.py", line 19, in send_password_reset_email
    user=user, token=token))
  File "/Users/jinmc/Developer/python/flaskBlog/app/email.py", line 9, in send_email
    mail.send(msg)
  File "/Users/jinmc/Developer/python/flaskBlog/venv/lib/python3.6/site-packages/flask_mail.py", line 491, in send
    with self.connect() as connection:
  File "/Users/jinmc/Developer/python/flaskBlog/venv/lib/python3.6/site-packages/flask_mail.py", line 144, in __enter__
    self.host = self.configure_host()
  File "/Users/jinmc/Developer/python/flaskBlog/venv/lib/python3.6/site-packages/flask_mail.py", line 165, in configure_host
    host.login(self.mail.username, self.mail.password)
  File "/Library/Frameworks/Python.framework/Versions/3.6/lib/python3.6/smtplib.py", line 730, in login
    raise last_exception
  File "/Library/Frameworks/Python.framework/Versions/3.6/lib/python3.6/smtplib.py", line 721, in login
    initial_response_ok=initial_response_ok)
  File "/Library/Frameworks/Python.framework/Versions/3.6/lib/python3.6/smtplib.py", line 642, in auth
    raise SMTPAuthenticationError(code, resp)
smtplib.SMTPAuthenticationError: (535, b'5.7.8 Username and Password not accepted. Learn more at\n5.7.8  https://support.google.com/mail/?p=BadCredentials k50sm5542269qtc.90 - gsmtp')
2020-02-24 00:31:11,541 INFO: Microblog startup: [in /Users/jinmc/Developer/python/flaskBlog/app/__init__.py:42]
2020-02-24 00:31:24,226 ERROR: Exception on /reset_password_request [POST]: [in /Users/jinmc/Developer/python/flaskBlog/venv/lib/python3.6/site-packages/flask/app.py:1891]
Traceback (most recent call last):
  File "/Users/jinmc/Developer/python/flaskBlog/venv/lib/python3.6/site-packages/flask/app.py", line 2446, in wsgi_app
    response = self.full_dispatch_request()
  File "/Users/jinmc/Developer/python/flaskBlog/venv/lib/python3.6/site-packages/flask/app.py", line 1951, in full_dispatch_request
    rv = self.handle_user_exception(e)
  File "/Users/jinmc/Developer/python/flaskBlog/venv/lib/python3.6/site-packages/flask/app.py", line 1820, in handle_user_exception
    reraise(exc_type, exc_value, tb)
  File "/Users/jinmc/Developer/python/flaskBlog/venv/lib/python3.6/site-packages/flask/_compat.py", line 39, in reraise
    raise value
  File "/Users/jinmc/Developer/python/flaskBlog/venv/lib/python3.6/site-packages/flask/app.py", line 1949, in full_dispatch_request
    rv = self.dispatch_request()
  File "/Users/jinmc/Developer/python/flaskBlog/venv/lib/python3.6/site-packages/flask/app.py", line 1935, in dispatch_request
    return self.view_functions[rule.endpoint](**req.view_args)
  File "/Users/jinmc/Developer/python/flaskBlog/app/routes.py", line 166, in reset_password_request
    send_password_reset_email(user)
  File "/Users/jinmc/Developer/python/flaskBlog/app/email.py", line 19, in send_password_reset_email
    user=user, token=token))
  File "/Users/jinmc/Developer/python/flaskBlog/app/email.py", line 9, in send_email
    mail.send(msg)
  File "/Users/jinmc/Developer/python/flaskBlog/venv/lib/python3.6/site-packages/flask_mail.py", line 491, in send
    with self.connect() as connection:
  File "/Users/jinmc/Developer/python/flaskBlog/venv/lib/python3.6/site-packages/flask_mail.py", line 144, in __enter__
    self.host = self.configure_host()
  File "/Users/jinmc/Developer/python/flaskBlog/venv/lib/python3.6/site-packages/flask_mail.py", line 165, in configure_host
    host.login(self.mail.username, self.mail.password)
  File "/Library/Frameworks/Python.framework/Versions/3.6/lib/python3.6/smtplib.py", line 730, in login
    raise last_exception
  File "/Library/Frameworks/Python.framework/Versions/3.6/lib/python3.6/smtplib.py", line 721, in login
    initial_response_ok=initial_response_ok)
  File "/Library/Frameworks/Python.framework/Versions/3.6/lib/python3.6/smtplib.py", line 642, in auth
    raise SMTPAuthenticationError(code, resp)
smtplib.SMTPAuthenticationError: (535, b'5.7.8 Username and Password not accepted. Learn more at\n5.7.8  https://support.google.com/mail/?p=BadCredentials w53sm5548533qtb.91 - gsmtp')
2020-02-24 00:34:54,540 INFO: Microblog startup: [in /Users/jinmc/Developer/python/flaskBlog/app/__init__.py:42]
2020-02-24 00:35:03,741 ERROR: Exception on /reset_password_request [POST]: [in /Users/jinmc/Developer/python/flaskBlog/venv/lib/python3.6/site-packages/flask/app.py:1891]
Traceback (most recent call last):
  File "/Users/jinmc/Developer/python/flaskBlog/venv/lib/python3.6/site-packages/flask/app.py", line 2446, in wsgi_app
    response = self.full_dispatch_request()
  File "/Users/jinmc/Developer/python/flaskBlog/venv/lib/python3.6/site-packages/flask/app.py", line 1951, in full_dispatch_request
    rv = self.handle_user_exception(e)
  File "/Users/jinmc/Developer/python/flaskBlog/venv/lib/python3.6/site-packages/flask/app.py", line 1820, in handle_user_exception
    reraise(exc_type, exc_value, tb)
  File "/Users/jinmc/Developer/python/flaskBlog/venv/lib/python3.6/site-packages/flask/_compat.py", line 39, in reraise
    raise value
  File "/Users/jinmc/Developer/python/flaskBlog/venv/lib/python3.6/site-packages/flask/app.py", line 1949, in full_dispatch_request
    rv = self.dispatch_request()
  File "/Users/jinmc/Developer/python/flaskBlog/venv/lib/python3.6/site-packages/flask/app.py", line 1935, in dispatch_request
    return self.view_functions[rule.endpoint](**req.view_args)
  File "/Users/jinmc/Developer/python/flaskBlog/app/routes.py", line 166, in reset_password_request
    send_password_reset_email(user)
  File "/Users/jinmc/Developer/python/flaskBlog/app/email.py", line 19, in send_password_reset_email
    user=user, token=token))
  File "/Users/jinmc/Developer/python/flaskBlog/app/email.py", line 9, in send_email
    mail.send(msg)
  File "/Users/jinmc/Developer/python/flaskBlog/venv/lib/python3.6/site-packages/flask_mail.py", line 492, in send
    message.send(connection)
  File "/Users/jinmc/Developer/python/flaskBlog/venv/lib/python3.6/site-packages/flask_mail.py", line 427, in send
    connection.send(self)
  File "/Users/jinmc/Developer/python/flaskBlog/venv/lib/python3.6/site-packages/flask_mail.py", line 178, in send
    "The message does not specify a sender and a default sender "
AssertionError: The message does not specify a sender and a default sender has not been configured
2020-02-24 00:41:06,877 INFO: Microblog startup: [in /Users/jinmc/Developer/python/flaskBlog/app/__init__.py:42]
2020-02-24 00:41:22,095 ERROR: Exception on /reset_password_request [POST]: [in /Users/jinmc/Developer/python/flaskBlog/venv/lib/python3.6/site-packages/flask/app.py:1891]
Traceback (most recent call last):
  File "/Users/jinmc/Developer/python/flaskBlog/venv/lib/python3.6/site-packages/flask/app.py", line 2446, in wsgi_app
    response = self.full_dispatch_request()
  File "/Users/jinmc/Developer/python/flaskBlog/venv/lib/python3.6/site-packages/flask/app.py", line 1951, in full_dispatch_request
    rv = self.handle_user_exception(e)
  File "/Users/jinmc/Developer/python/flaskBlog/venv/lib/python3.6/site-packages/flask/app.py", line 1820, in handle_user_exception
    reraise(exc_type, exc_value, tb)
  File "/Users/jinmc/Developer/python/flaskBlog/venv/lib/python3.6/site-packages/flask/_compat.py", line 39, in reraise
    raise value
  File "/Users/jinmc/Developer/python/flaskBlog/venv/lib/python3.6/site-packages/flask/app.py", line 1949, in full_dispatch_request
    rv = self.dispatch_request()
  File "/Users/jinmc/Developer/python/flaskBlog/venv/lib/python3.6/site-packages/flask/app.py", line 1935, in dispatch_request
    return self.view_functions[rule.endpoint](**req.view_args)
  File "/Users/jinmc/Developer/python/flaskBlog/app/routes.py", line 166, in reset_password_request
    send_password_reset_email(user)
  File "/Users/jinmc/Developer/python/flaskBlog/app/email.py", line 19, in send_password_reset_email
    user=user, token=token))
  File "/Users/jinmc/Developer/python/flaskBlog/app/email.py", line 6, in send_email
    msg = Message(subject, sender, recipients=recipients)
TypeError: __init__() got multiple values for argument 'recipients'
2020-02-24 00:46:59,477 INFO: Microblog startup: [in /Users/jinmc/Developer/python/flaskBlog/app/__init__.py:42]
