2020-02-22 18:12:42,881 ERROR: Exception on /explore [GET]: [in /Users/jinmc/Developer/python/flaskBlog/venv/lib/python3.6/site-packages/flask/app.py:1891]
Traceback (most recent call last):
  File "/Users/jinmc/Developer/python/flaskBlog/venv/lib/python3.6/site-packages/flask/app.py", line 2446, in wsgi_app
    response = self.full_dispatch_request()
  File "/Users/jinmc/Developer/python/flaskBlog/venv/lib/python3.6/site-packages/flask/app.py", line 1951, in full_dispatch_request
    rv = self.handle_user_exception(e)
  File "/Users/jinmc/Developer/python/flaskBlog/venv/lib/python3.6/site-packages/flask/app.py", line 1820, in handle_user_exception
    reraise(exc_type, exc_value, tb)
  File "/Users/jinmc/Developer/python/flaskBlog/venv/lib/python3.6/site-packages/flask/_compat.py", line 39, in reraise
    raise value
  File "/Users/jinmc/Developer/python/flaskBlog/venv/lib/python3.6/site-packages/flask/app.py", line 1949, in full_dispatch_request
    rv = self.dispatch_request()
  File "/Users/jinmc/Developer/python/flaskBlog/venv/lib/python3.6/site-packages/flask/app.py", line 1935, in dispatch_request
    return self.view_functions[rule.endpoint](**req.view_args)
  File "/Users/jinmc/Developer/python/flaskBlog/venv/lib/python3.6/site-packages/flask_login/utils.py", line 272, in decorated_view
    return func(*args, **kwargs)
  File "/Users/jinmc/Developer/python/flaskBlog/app/routes.py", line 46, in explore
    return render_template('index.html', title='Explore', posts=posts)
  File "/Users/jinmc/Developer/python/flaskBlog/venv/lib/python3.6/site-packages/flask/templating.py", line 140, in render_template
    ctx.app,
  File "/Users/jinmc/Developer/python/flaskBlog/venv/lib/python3.6/site-packages/flask/templating.py", line 120, in _render
    rv = template.render(context)
  File "/Users/jinmc/Developer/python/flaskBlog/venv/lib/python3.6/site-packages/jinja2/environment.py", line 1090, in render
    self.environment.handle_exception()
  File "/Users/jinmc/Developer/python/flaskBlog/venv/lib/python3.6/site-packages/jinja2/environment.py", line 832, in handle_exception
    reraise(*rewrite_traceback_stack(source=source))
  File "/Users/jinmc/Developer/python/flaskBlog/venv/lib/python3.6/site-packages/jinja2/_compat.py", line 28, in reraise
    raise value.with_traceback(tb)
  File "/Users/jinmc/Developer/python/flaskBlog/app/templates/index.html", line 1, in top-level template code
    {% extends "base.html" %}
  File "/Users/jinmc/Developer/python/flaskBlog/app/templates/base.html", line 31, in top-level template code
    {% block content %}{% endblock %}
  File "/Users/jinmc/Developer/python/flaskBlog/app/templates/index.html", line 4, in block "content"
    <h1>Hi, {{ user.username }}!</h1>
  File "/Users/jinmc/Developer/python/flaskBlog/venv/lib/python3.6/site-packages/jinja2/environment.py", line 471, in getattr
    return getattr(obj, attribute)
jinja2.exceptions.UndefinedError: 'user' is undefined
2020-02-22 18:13:16,972 ERROR: Exception on /explore [GET]: [in /Users/jinmc/Developer/python/flaskBlog/venv/lib/python3.6/site-packages/flask/app.py:1891]
Traceback (most recent call last):
  File "/Users/jinmc/Developer/python/flaskBlog/venv/lib/python3.6/site-packages/flask/app.py", line 2446, in wsgi_app
    response = self.full_dispatch_request()
  File "/Users/jinmc/Developer/python/flaskBlog/venv/lib/python3.6/site-packages/flask/app.py", line 1951, in full_dispatch_request
    rv = self.handle_user_exception(e)
  File "/Users/jinmc/Developer/python/flaskBlog/venv/lib/python3.6/site-packages/flask/app.py", line 1820, in handle_user_exception
    reraise(exc_type, exc_value, tb)
  File "/Users/jinmc/Developer/python/flaskBlog/venv/lib/python3.6/site-packages/flask/_compat.py", line 39, in reraise
    raise value
  File "/Users/jinmc/Developer/python/flaskBlog/venv/lib/python3.6/site-packages/flask/app.py", line 1949, in full_dispatch_request
    rv = self.dispatch_request()
  File "/Users/jinmc/Developer/python/flaskBlog/venv/lib/python3.6/site-packages/flask/app.py", line 1935, in dispatch_request
    return self.view_functions[rule.endpoint](**req.view_args)
  File "/Users/jinmc/Developer/python/flaskBlog/venv/lib/python3.6/site-packages/flask_login/utils.py", line 272, in decorated_view
    return func(*args, **kwargs)
  File "/Users/jinmc/Developer/python/flaskBlog/app/routes.py", line 46, in explore
    return render_template('index.html', title='Explore', posts=posts)
  File "/Users/jinmc/Developer/python/flaskBlog/venv/lib/python3.6/site-packages/flask/templating.py", line 140, in render_template
    ctx.app,
  File "/Users/jinmc/Developer/python/flaskBlog/venv/lib/python3.6/site-packages/flask/templating.py", line 120, in _render
    rv = template.render(context)
  File "/Users/jinmc/Developer/python/flaskBlog/venv/lib/python3.6/site-packages/jinja2/environment.py", line 1090, in render
    self.environment.handle_exception()
  File "/Users/jinmc/Developer/python/flaskBlog/venv/lib/python3.6/site-packages/jinja2/environment.py", line 832, in handle_exception
    reraise(*rewrite_traceback_stack(source=source))
  File "/Users/jinmc/Developer/python/flaskBlog/venv/lib/python3.6/site-packages/jinja2/_compat.py", line 28, in reraise
    raise value.with_traceback(tb)
  File "/Users/jinmc/Developer/python/flaskBlog/app/templates/index.html", line 1, in top-level template code
    {% extends "base.html" %}
  File "/Users/jinmc/Developer/python/flaskBlog/app/templates/base.html", line 31, in top-level template code
    {% block content %}{% endblock %}
  File "/Users/jinmc/Developer/python/flaskBlog/app/templates/index.html", line 4, in block "content"
    <h1>Hi, {{ user.username }}!</h1>
  File "/Users/jinmc/Developer/python/flaskBlog/venv/lib/python3.6/site-packages/jinja2/environment.py", line 471, in getattr
    return getattr(obj, attribute)
jinja2.exceptions.UndefinedError: 'user' is undefined
2020-02-22 18:18:10,343 INFO: Microblog startup: [in /Users/jinmc/Developer/python/flaskBlog/app/__init__.py:40]
2020-02-22 18:18:19,937 ERROR: Exception on /explore [GET]: [in /Users/jinmc/Developer/python/flaskBlog/venv/lib/python3.6/site-packages/flask/app.py:1891]
Traceback (most recent call last):
  File "/Users/jinmc/Developer/python/flaskBlog/venv/lib/python3.6/site-packages/flask/app.py", line 2446, in wsgi_app
    response = self.full_dispatch_request()
  File "/Users/jinmc/Developer/python/flaskBlog/venv/lib/python3.6/site-packages/flask/app.py", line 1951, in full_dispatch_request
    rv = self.handle_user_exception(e)
  File "/Users/jinmc/Developer/python/flaskBlog/venv/lib/python3.6/site-packages/flask/app.py", line 1820, in handle_user_exception
    reraise(exc_type, exc_value, tb)
  File "/Users/jinmc/Developer/python/flaskBlog/venv/lib/python3.6/site-packages/flask/_compat.py", line 39, in reraise
    raise value
  File "/Users/jinmc/Developer/python/flaskBlog/venv/lib/python3.6/site-packages/flask/app.py", line 1949, in full_dispatch_request
    rv = self.dispatch_request()
  File "/Users/jinmc/Developer/python/flaskBlog/venv/lib/python3.6/site-packages/flask/app.py", line 1935, in dispatch_request
    return self.view_functions[rule.endpoint](**req.view_args)
  File "/Users/jinmc/Developer/python/flaskBlog/venv/lib/python3.6/site-packages/flask_login/utils.py", line 272, in decorated_view
    return func(*args, **kwargs)
  File "/Users/jinmc/Developer/python/flaskBlog/app/routes.py", line 46, in explore
    return render_template('index.html', title='Explore', posts=posts)
  File "/Users/jinmc/Developer/python/flaskBlog/venv/lib/python3.6/site-packages/flask/templating.py", line 140, in render_template
    ctx.app,
  File "/Users/jinmc/Developer/python/flaskBlog/venv/lib/python3.6/site-packages/flask/templating.py", line 120, in _render
    rv = template.render(context)
  File "/Users/jinmc/Developer/python/flaskBlog/venv/lib/python3.6/site-packages/jinja2/environment.py", line 1090, in render
    self.environment.handle_exception()
  File "/Users/jinmc/Developer/python/flaskBlog/venv/lib/python3.6/site-packages/jinja2/environment.py", line 832, in handle_exception
    reraise(*rewrite_traceback_stack(source=source))
  File "/Users/jinmc/Developer/python/flaskBlog/venv/lib/python3.6/site-packages/jinja2/_compat.py", line 28, in reraise
    raise value.with_traceback(tb)
  File "/Users/jinmc/Developer/python/flaskBlog/app/templates/index.html", line 1, in top-level template code
    {% extends "base.html" %}
  File "/Users/jinmc/Developer/python/flaskBlog/app/templates/base.html", line 31, in top-level template code
    {% block content %}{% endblock %}
  File "/Users/jinmc/Developer/python/flaskBlog/app/templates/index.html", line 4, in block "content"
    <h1>Hi, {{ user.username }}!</h1>
  File "/Users/jinmc/Developer/python/flaskBlog/venv/lib/python3.6/site-packages/jinja2/environment.py", line 471, in getattr
    return getattr(obj, attribute)
jinja2.exceptions.UndefinedError: 'user' is undefined
2020-02-22 18:19:43,771 INFO: Microblog startup: [in /Users/jinmc/Developer/python/flaskBlog/app/__init__.py:40]
